Workbook

Sheet 学科映射关系
A1: 序号 | B1: 门类代码 | C1: 学科门类 | D1: 一级学科代码 | E1: 一级学科名称 | F1: 目录年度 | G1: 软科世界一流学科对应名称 | H1: QS对应的学科名称 | I1: U.S.NEWS学科排名对应名称 | J1: THE对应领域
A2: 1 | B2: 01 | C2: 哲学 | D2: 0101 | E2: 哲学 | F2: 2022 | H2: 哲学 | J2: 艺术与人文
A3: 2 | B3: 01 | C3: 哲学 | D3: 0151 | E3: 应用伦理 | F3: 2022
A4: 3 | B4: 02 | C4: 经济学 | D4: 0201 | E4: 理论经济学 | F4: 2022 | G4: 经济学 | H4: 发展研究 | I4: 商业与经济 | J4: 商业与经济
A5: 4 | B5: 02 | C5: 经济学 | D5: 0202 | E5: 应用经济学 | F5: 2022 | G5: 金融学、经济学 | H5: 经济与计量经济学 | I5: 商业与经济 | J5: 商业与经济
A6: 5 | B6: 02 | C6: 经济学 | D6: 0251 | E6: 金融 | F6: 2022
A7: 6 | B7: 02 | C7: 经济学 | D7: 0252 | E7: 应用统计 | F7: 2022
A8: 7 | B8: 02 | C8: 经济学 | D8: 0253 | E8: 税务 | F8: 2022
A9: 8 | B9: 02 | C9: 经济学 | D9: 0254 | E9: 国际商务 | F9: 2022
A10: 9 | B10: 02 | C10: 经济学 | D10: 0255 | E10: 保险 | F10: 2022
A11: 10 | B11: 02 | C11: 经济学 | D11: 0256 | E11: 资产评估 | F11: 2022
A12: 11 | B12: 02 | C12: 经济学 | D12: 0258 | E12: 数字经济 | F12: 2022
A13: 12 | B13: 03 | C13: 法学 | D13: 0301 | E13: 法学 | F13: 2022 | G13: 法学 | H13: 法律与法律研究 | J13: 法学
A14: 13 | B14: 03 | C14: 法学 | D14: 0302 | E14: 政治学 | F14: 2022 | G14: 政治学 | H14: 政治学 | J14: 社会科学
A15: 14 | B15: 03 | C15: 法学 | D15: 0303 | E15: 社会学 | F15: 2022 | G15: 社会学 | H15: 社会学 | J15: 社会科学
A16: 15 | B16: 03 | C16: 法学 | D16: 0304 | E16: 民族学 | F16: 2022 | J16: 社会科学
A17: 16 | B17: 03 | C17: 法学 | D17: 0305 | E17: 马克思主义理论 | F17: 2022
A18: 17 | B18: 03 | C18: 法学 | D18: 0306 | E18: 公安学 | F18: 2022
A19: 18 | B19: 03 | C19: 法学 | D19: 0307 | E19: 中共党史党建学 | F19: 2022
A20: 19 | B20: 03 | C20: 法学 | D20: 0308 | E20: 纪检监察学 | F20: 2022
A21: 20 | B21: 03 | C21: 法学 | D21: 0351 | E21: 法律 | F21: 2022
A22: 21 | B22: 03 | C22: 法学 | D22: 0352 | E22: 社会工作 | F22: 2022
A23: 22 | B23: 03 | C23: 法学 | D23: 0353 | E23: 警务 | F23: 2022
A24: 23 | B24: 03 | C24: 法学 | D24: 0354 | E24: 知识产权 | F24: 2022
A25: 24 | B25: 03 | C25: 法学 | D25: 0355 | E25: 国际事务 | F25: 2022
A26: 25 | B26: 04 | C26: 教育学 | D26: 0401 | E26: 教育学 | F26: 2022 | G26: 教育学 | H26: 教育与培训 | I26: 教育学和教育研究 | J26: 教育学
A27: 26 | B27: 04 | C27: 教育学 | D27: 0402 | E27: 心理学 | F27: 2022 | G27: 心理学 | H27: 心理学 | I27: 精神病学与心理学 | J27: 心理学
A28: 27 | B28: 04 | C28: 教育学 | D28: 0403 | E28: 体育学 | F28: 2022 | H28: 体育相关学科
A29: 28 | B29: 04 | C29: 教育学 | D29: 0451 | E29: 教育 | F29: 2022 | J29: 教育学
A30: 29 | B30: 04 | C30: 教育学 | D30: 0452 | E30: 体育 | F30: 2022
A31: 30 | B31: 04 | C31: 教育学 | D31: 0453 | E31: 国际中文教育 | F31: 2022
A32: 31 | B32: 04 | C32: 教育学 | D32: 0454 | E32: 应用心理 | F32: 2022 | J32: 心理学
A33: 32 | B33: 05 | C33: 文学 | D33: 0501 | E33: 中国语言文学 | F33: 2022 | I33: 艺术与人文 | J33: 艺术与人文
A34: 33 | B34: 05 | C34: 文学 | D34: 0502 | E34: 外国语言文学 | F34: 2022 | H34: 现代语言文学 | I34: 艺术与人文 | J34: 艺术与人文
A35: 34 | B35: 05 | C35: 文学 | D35: 0503 | E35: 新闻传播学 | F35: 2022 | G35: 新闻传播学 | H35: 传播与媒体研究 | J35: 社会科学
A36: 35 | B36: 05 | C36: 文学 | D36: 0551 | E36: 翻译 | F36: 2022
A37: 36 | B37: 05 | C37: 文学 | D37: 0552 | E37: 新闻与传播 | F37: 2022
A38: 37 | B38: 05 | C38: 文学 | D38: 0553 | E38: 出版 | F38: 2022
A39: 38 | B39: 06 | C39: 历史学 | D39: 0601 | E39: 考古学 | F39: 2022 | H39: 考古学 | J39: 艺术与人文
A40: 39 | B40: 06 | C40: 历史学 | D40: 0602 | E40: 中国史 | F40: 2022 | J40: 艺术与人文
...

Sheet Sheet1
A1: 榜单名称 | B1: 榜单学科 | C1: 对应一级学科 | D1: 榜单学科 | E1: 匹对情况
A2: 软科世界一流学科排名 | B2: 数学 | C2: 数学 | D2: 数学 | E2: =VLOOKUP(B2,学科映射关系!G:G,1,FALSE) -> 数学
A3: 软科世界一流学科排名 | B3: 物理学 | C3: 物理学 | D3: 物理学 | E3: =VLOOKUP(B3,学科映射关系!G:G,1,FALSE) -> 物理学
A4: 软科世界一流学科排名 | B4: 化学 | C4: 化学 | D4: 化学 | E4: =VLOOKUP(B4,学科映射关系!G:G,1,FALSE) -> 化学
A5: 软科世界一流学科排名 | B5: 地球科学 | C5: 地球物理学、地质资源与地质工程、地质学 | D5: 地球科学 | E5: =VLOOKUP(B5,学科映射关系!G:G,1,FALSE) -> 地球科学
A6: 软科世界一流学科排名 | B6: 地理学 | C6: 地理学 | D6: 地理学 | E6: =VLOOKUP(B6,学科映射关系!G:G,1,FALSE) -> 地理学
A7: 软科世界一流学科排名 | B7: 生态学 | C7: 生态学 | D7: 生态学 | E7: =VLOOKUP(B7,学科映射关系!G:G,1,FALSE) -> 生态学
A8: 软科世界一流学科排名 | B8: 机械工程 | C8: 机械工程 | D8: 机械工程 | E8: =VLOOKUP(B8,学科映射关系!G:G,1,FALSE) -> 机械工程
A9: 软科世界一流学科排名 | B9: 电力电子工程 | C9: 电子科学与技术、电气工程 | D9: 电力电子工程 | E9: =VLOOKUP(B9,学科映射关系!G:G,1,FALSE) -> 电力电子工程
A10: 软科世界一流学科排名 | B10: 控制科学与工程 | C10: 控制科学与工程 | D10: 控制科学与工程 | E10: =VLOOKUP(B10,学科映射关系!G:G,1,FALSE) -> 控制科学与工程
A11: 软科世界一流学科排名 | B11: 通信工程 | C11: 信息与通信工程 | D11: 通信工程 | E11: =VLOOKUP(B11,学科映射关系!G:G,1,FALSE) -> 通信工程
A12: 软科世界一流学科排名 | B12: 仪器科学 | C12: 仪器科学与技术 | D12: 仪器科学 | E12: =VLOOKUP(B12,学科映射关系!G:G,1,FALSE) -> 仪器科学
A13: 软科世界一流学科排名 | B13: 生物医学工程 | C13: 生物医学工程 | D13: 生物医学工程 | E13: =VLOOKUP(B13,学科映射关系!G:G,1,FALSE) -> 生物医学工程
... A37: 软科世界一流学科排名 | B37: 护理学 | C37: 护理学 | D37: 护理学 | E37: =VLOOKUP(B37,学科映射关系!G:G,1,FALSE) -> 护理学
A38: 软科世界一流学科排名 | B38: 医学技术 | D38: 医学技术 | E38: =VLOOKUP(B38,学科映射关系!G:G,1,FALSE) -> #N/A
A39: 软科世界一流学科排名 | B39: 药学 | C39: 药学 | D39: 药学 | E39: =VLOOKUP(B39,学科映射关系!G:G,1,FALSE) -> 药学
A40: 软科世界一流学科排名 | B40: 经济学 | C40: 应用经济学、理论经济学 | D40: 经济学 | E40: =VLOOKUP(B40,学科映射关系!G:G,1,FALSE) -> 经济学
A41: 软科世界一流学科排名 | B41: 统计学 | C41: 统计学 | D41: 统计学 | E41: =VLOOKUP(B41,学科映射关系!G:G,1,FALSE) -> 统计学
A42: 软科世界一流学科排名 | B42: 法学 | C42: 法学 | D42: 法学 | E42: =VLOOKUP(B42,学科映射关系!G:G,1,FALSE) -> 法学
A43: 软科世界一流学科排名 | B43: 政治学 | C43: 政治学 | D43: 政治学 | E43: =VLOOKUP(B43,学科映射关系!G:G,1,FALSE) -> 政治学
A44: 软科世界一流学科排名 | B44: 社会学 | C44: 社会学 | D44: 社会学 | E44: =VLOOKUP(B44,学科映射关系!G:G,1,FALSE) -> 社会学
A45: 软科世界一流学科排名 | B45: 教育学 | C45: 教育学 | D45: 教育学 | E45: =VLOOKUP(B45,学科映射关系!G:G,1,FALSE) -> 教育学
A46: 软科世界一流学科排名 | B46: 新闻传播学 | C46: 新闻传播学 | D46: 新闻传播学 | E46: =VLOOKUP(B46,学科映射关系!G:G,1,FALSE) -> 新闻传播学
A47: 软科世界一流学科排名 | B47: 心理学 | C47: 心理学 | D47: 心理学 | E47: =VLOOKUP(B47,学科映射关系!G:G,1,FALSE) -> 心理学
A48: 软科世界一流学科排名 | B48: 工商管理 | C48: 工商管理学 | D48: 工商管理 | E48: =VLOOKUP(B48,学科映射关系!G:G,1,FALSE) -> 工商管理
A49: 软科世界一流学科排名 | B49: 金融学 | C49: 应用经济学 | D49: 金融学 | E49: =VLOOKUP(B49,学科映射关系!G:G,1,FALSE) -> #N/A
A50: 软科世界一流学科排名 | B50: 管理学 | C50: 管理科学与工程 | D50: 管理学 | E50: =VLOOKUP(B50,学科映射关系!G:G,1,FALSE) -> 管理学
... A56: 软科世界一流学科排名 | B56: 纺织科学与工程 | C56: 纺织科学与工程 | D56: 纺织科学与工程 | E56: =VLOOKUP(B56,学科映射关系!G:G,1,FALSE) -> 纺织科学与工程
A57: QS世界学科排名 | B57: 会计与金融 | C57: 工商管理学、应用经济学 | D57: 会计与金融 | E57: =VLOOKUP(B57,学科映射关系!H:H,1,FALSE) -> #N/A
A58: QS世界学科排名 | B58: 农学与林学 | C58: 草学、畜牧学、林学、林业工程、农业工程、农业资源与环境、水产、园艺学、植物保护、作物学 | D58: 农学与林学 | E58: =VLOOKUP(B58,学科映射关系!H:H,1,FALSE) -> #N/A
A59: QS世界学科排名 | B59: 解剖学和生理学 | C59: 基础医学 | D59: 解剖学和生理学 | E59: =VLOOKUP(B59,学科映射关系!H:H,1,FALSE) -> #N/A
A60: QS世界学科排名 | B60: 人类学 | D60: 人类学 | E60: =VLOOKUP(B60,学科映射关系!H:H,1,FALSE) -> #N/A
A61: QS世界学科排名 | B61: 考古学 | C61: 考古学 | D61: 考古学 | E61: =VLOOKUP(B61,学科映射关系!H:H,1,FALSE) -> 考古学
A62: QS世界学科排名 | B62: 建筑学 | C62: 建筑学 | D62: 建筑学 | E62: =VLOOKUP(B62,学科映射关系!H:H,1,FALSE) -> 建筑学
A63: QS世界学科排名 | B63: 艺术与设计 | C63: 艺术学、设计学 | D63: 艺术与设计 | E63: =VLOOKUP(B63,学科映射关系!H:H,1,FALSE) -> 艺术与设计
A64: QS世界学科排名 | B64: 生物科学 | C64: 生物学 | D64: 生物科学 | E64: =VLOOKUP(B64,学科映射关系!H:H,1,FALSE) -> 生物科学
A65: QS世界学科排名 | B65: 商务与管理 | C65: 工商管理学 | D65: 商务与管理 | E65: =VLOOKUP(B65,学科映射关系!H:H,1,FALSE) -> 商务与管理
A66: QS世界学科排名 | B66: 化学 | C66: 化学 | D66: 化学 | E66: =VLOOKUP(B66,学科映射关系!H:H,1,FALSE) -> #N/A
A67: QS世界学科排名 | B67: 古典文学与古代史 | C67: 世界史、外国语言文学 | D67: 古典文学与古代史 | E67: =VLOOKUP(B67,学科映射关系!H:H,1,FALSE) -> #N/A
A68: QS世界学科排名 | B68: 传播与媒体研究 | C68: 新闻传播学 | D68: 传播与媒体研究 | E68: =VLOOKUP(B68,学科映射关系!H:H,1,FALSE) -> 传播与媒体研究
...
